Workbook

Sheet Time Entries
A1: Date | B1: Day | C1: Project | D1: Father Task | E1: Sub Task | F1: Sub Task Code | G1: Category | H1: Start Time | I1: End Time | J1: Duration (h) | K1: Description | L1: Break Info
A2: 46230 | B2: Mon | C2: AI-AutoTest | D2: Create MCP tool | E2: MCP log | F2: PRJ-1-KPI-1-ST-1 | G2: MCPTOOL | H2: 0.58611111 | I2: 0.72976852 | J2: =IF(AND(H2<>"",I2<>""),(I2-H2)*24,"") | K2: Done MCP tool log | M2: =IF(C2<>"",C2,"") | N2: =IF(D2<>"",D2,"") | O2: =M2&": "&N2 | P2: =IF(O2="","",IF(COUNTIF($O$1:O1,O2)=0,MAX($P$1:P1)+1,"")) | Q2: =IF(A2="","",COUNTIF($A$2:A2,A2)) | R2: =IF(A2="","",1)
A3: 46232 | B3: Wed | C3: web fix | D3: Fix the project web running correct | E3: Running checker the UI/UX | F3: PRJ-3-KPI-2-ST-1 | G3: Development | H3: 0.4393287 | I3: 0.46021991 | J3: =IF(AND(H3<>"",I3<>""),(I3-H3)*24,"") | K3: feat: enforce starting subtask only if created + add subtask start command | M3: =IF(C3<>"",C3,M2) | N3: =IF(D3<>"",D3,N2) | O3: =M3&": "&N3 | P3: =IF(O3="","",IF(COUNTIF($O$1:O2,O3)=0,MAX($P$1:P2)+1,"")) | Q3: =IF(A3="","",COUNTIF($A$2:A3,A3)) | R3: =IF(A3="","",MAX($R$1:R2)+1)
A4: 46232 | B4: Wed | C4: web fix | D4: Fix the project web running correct | E4: Running checker the UI/UX | F4: PRJ-3-KPI-2-ST-1 | G4: Development | H4: 0.4393287 | I4: 0.46027778 | J4: =IF(AND(H4<>"",I4<>""),(I4-H4)*24,"") | K4: feat: enforce starting subtask only if created + add subtask start command | M4: =IF(C4<>"",C4,M3) | N4: =IF(D4<>"",D4,N3) | O4: =M4&": "&N4 | P4: =IF(O4="","",IF(COUNTIF($O$1:O3,O4)=0,MAX($P$1:P3)+1,"")) | Q4: =IF(A4="","",COUNTIF($A$2:A4,A4)) | R4: =IF(A4="","",MAX($R$1:R3)+1)
A5: 46232 | B5: Wed | C5: web fix | D5: Fix the project web running correct | E5: Running checker the UI/UX | F5: PRJ-3-KPI-2-ST-1 | G5: Development | H5: 0.4393287 | I5: 0.46040509 | J5: =IF(AND(H5<>"",I5<>""),(I5-H5)*24,"") | K5: feat: enforce starting subtask only if created + add subtask start command | M5: =IF(C5<>"",C5,M4) | N5: =IF(D5<>"",D5,N4) | O5: =M5&": "&N5 | P5: =IF(O5="","",IF(COUNTIF($O$1:O4,O5)=0,MAX($P$1:P4)+1,"")) | Q5: =IF(A5="","",COUNTIF($A$2:A5,A5)) | R5: =IF(A5="","",MAX($R$1:R4)+1)
A6: 46232 | B6: Wed | C6: web fix | D6: Fix the project web running correct | E6: Running checker the UI/UX | F6: PRJ-3-KPI-2-ST-1 | G6: Development | H6: 0.4393287 | I6: 0.46045139 | J6: =IF(AND(H6<>"",I6<>""),(I6-H6)*24,"") | K6: feat: enforce starting subtask only if created + add subtask start command | M6: =IF(C6<>"",C6,M5) | N6: =IF(D6<>"",D6,N5) | O6: =M6&": "&N6 | P6: =IF(O6="","",IF(COUNTIF($O$1:O5,O6)=0,MAX($P$1:P5)+1,"")) | Q6: =IF(A6="","",COUNTIF($A$2:A6,A6)) | R6: =IF(A6="","",MAX($R$1:R5)+1)
A7: 46232 | B7: Wed | C7: web fix | D7: Fix the project web running correct | E7: Running checker the UI/UX | F7: PRJ-3-KPI-2-ST-1 | G7: Development | H7: 0.4393287 | I7: 0.46049769 | J7: =IF(AND(H7<>"",I7<>""),(I7-H7)*24,"") | K7: feat: enforce starting subtask only if created + add subtask start command | M7: =IF(C7<>"",C7,M6) | N7: =IF(D7<>"",D7,N6) | O7: =M7&": "&N7 | P7: =IF(O7="","",IF(COUNTIF($O$1:O6,O7)=0,MAX($P$1:P6)+1,"")) | Q7: =IF(A7="","",COUNTIF($A$2:A7,A7)) | R7: =IF(A7="","",MAX($R$1:R6)+1)
A8: 46232 | B8: Wed | C8: web fix | D8: Fix the project web running correct | E8: Running checker the UI/UX | F8: PRJ-3-KPI-2-ST-1 | G8: Development | H8: 0.4393287 | I8: 0.46054398 | J8: =IF(AND(H8<>"",I8<>""),(I8-H8)*24,"") | K8: feat: enforce starting subtask only if created + add subtask start command | M8: =IF(C8<>"",C8,M7) | N8: =IF(D8<>"",D8,N7) | O8: =M8&": "&N8 | P8: =IF(O8="","",IF(COUNTIF($O$1:O7,O8)=0,MAX($P$1:P7)+1,"")) | Q8: =IF(A8="","",COUNTIF($A$2:A8,A8)) | R8: =IF(A8="","",MAX($R$1:R7)+1)
A9: 46232 | B9: Wed | C9: web fix | D9: Fix the project web running correct | E9: Running checker the UI/UX | F9: PRJ-3-KPI-2-ST-1 | G9: Development | H9: 0.4393287 | I9: 0.46060185 | J9: =IF(AND(H9<>"",I9<>""),(I9-H9)*24,"") | K9: feat: enforce starting subtask only if created + add subtask start command | M9: =IF(C9<>"",C9,M8) | N9: =IF(D9<>"",D9,N8) | O9: =M9&": "&N9 | P9: =IF(O9="","",IF(COUNTIF($O$1:O8,O9)=0,MAX($P$1:P8)+1,"")) | Q9: =IF(A9="","",COUNTIF($A$2:A9,A9)) | R9: =IF(A9="","",MAX($R$1:R8)+1)
A10: 46232 | B10: Wed | C10: AI-Airtest | D10: Create MCP tool | E10: Fix MCP tool airtest | F10: PRJ-1-KPI-1-ST-2 | G10: Development | H10: 0.36893519 | I10: 0.46065972 | J10: =IF(AND(H10<>"",I10<>""),(I10-H10)*24,"") | K10: feat: enforce starting subtask only if created + add subtask start command | M10: =IF(C10<>"",C10,M9) | N10: =IF(D10<>"",D10,N9) | O10: =M10&": "&N10 | P10: =IF(O10="","",IF(COUNTIF($O$1:O9,O10)=0,MAX($P$1:P9)+1,"")) | Q10: =IF(A10="","",COUNTIF($A$2:A10,A10)) | R10: =IF(A10="","",MAX($R$1:R9)+1)
A11: 46232 | B11: Wed | C11: web fix | D11: Fix the project web running correct | E11: Running checker the UI/UX | F11: PRJ-3-KPI-2-ST-1 | G11: Development | H11: 0.65025463 | I11: 0.70479167 | J11: =IF(AND(H11<>"",I11<>""),(I11-H11)*24,"") | K11: feat: enforce starting subtask only if created + add subtask start command | L11: out of quota(11m); out of quota(86m) | M11: =IF(C11<>"",C11,M10) | N11: =IF(D11<>"",D11,N10) | O11: =M11&": "&N11 | P11: =IF(O11="","",IF(COUNTIF($O$1:O10,O11)=0,MAX($P$1:P10)+1,"")) | Q11: =IF(A11="","",COUNTIF($A$2:A11,A11)) | R11: =IF(A11="","",MAX($R$1:R10)+1)
A12: 46233 | B12: Thu | C12: AI-AutoTest | D12: Create MCP tool | E12: Create MCP Airtest report | F12: PRJ-1-KPI-1-ST-6 | G12: Development | H12: 0.56577546 | I12: 0.66146991 | J12: =IF(AND(H12<>"",I12<>""),(I12-H12)*24,"") | K12: Create the MCP can export the report after running AI | L12: End of the day, wait to tomorrow(899m); lunch(15m) | M12: =IF(C12<>"",C12,M11) | N12: =IF(D12<>"",D12,N11) | O12: =M12&": "&N12 | P12: =IF(O12="","",IF(COUNTIF($O$1:O11,O12)=0,MAX($P$1:P11)+1,"")) | Q12: =IF(A12="","",COUNTIF($A$2:A12,A12)) | R12: =IF(A12="","",MAX($R$1:R11)+1)
A13: 46233 | B13: Thu | C13: AI-AutoTest | D13: Create MCP tool | E13: Fix MCP tool airtest | F13: PRJ-1-KPI-1-ST-6 | G13: Development | H13: 0.56577546 | I13: 0.66188657 | J13: =IF(AND(H13<>"",I13<>""),(I13-H13)*24,"") | K13: Create the MCP can export the report after running AI | L13: End of the day, wait to tomorrow(899m); lunch(15m) | M13: =IF(C13<>"",C13,M12) | N13: =IF(D13<>"",D13,N12) | O13: =M13&": "&N13 | P13: =IF(O13="","",IF(COUNTIF($O$1:O12,O13)=0,MAX($P$1:P12)+1,"")) | Q13: =IF(A13="","",COUNTIF($A$2:A13,A13)) | R13: =IF(A13="","",MAX($R$1:R12)+1)
A14: 46233 | B14: Thu | C14: AI-AutoTest | D14: Create MCP tool | E14: Create MCP Airtest report | F14: PRJ-1-KPI-1-ST-6 | G14: Development | H14: 0.56577546 | I14: 0.66233796 | J14: =IF(AND(H14<>"",I14<>""),(I14-H14)*24,"") | K14: Create the MCP can export the report after running AI | L14: End of the day, wait to tomorrow(899m); lunch(15m) | M14: =IF(C14<>"",C14,M13) | N14: =IF(D14<>"",D14,N13) | O14: =M14&": "&N14 | P14: =IF(O14="","",IF(COUNTIF($O$1:O13,O14)=0,MAX($P$1:P13)+1,"")) | Q14: =IF(A14="","",COUNTIF($A$2:A14,A14)) | R14: =IF(A14="","",MAX($R$1:R13)+1)
A15: 46233 | B15: Thu | C15: AI-AutoTest | D15: Prompt AI | E15: MCP running test case | F15: PRJ-1-KPI-2-ST-1 | G15: Development | H15: 0.666875 | I15: 0.59390046 | J15: =IF(AND(H15<>"",I15<>""),(I15-H15)*24,"") | K15: fix the context system prompt to make it low cost | M15: =IF(C15<>"",C15,M14) | N15: =IF(D15<>"",D15,N14) | O15: =M15&": "&N15 | P15: =IF(O15="","",IF(COUNTIF($O$1:O14,O15)=0,MAX($P$1:P14)+1,"")) | Q15: =IF(A15="","",COUNTIF($A$2:A15,A15)) | R15: =IF(A15="","",MAX($R$1:R14)+1)
A16: 46238 | B16: Tue | C16: AI-AutoTest | D16: Prompt AI | E16: Convert knowledge AI | F16: PRJ-1-KPI-2-ST-1 | G16: Development | H16: 0.63006944 | I16: 0.74486111 | J16: =IF(AND(H16<>"",I16<>""),(I16-H16)*24,"") | K16: feat: enforce starting subtask only if created + add subtask start command | L16: break(48m) | M16: =IF(C16<>"",C16,M15) | N16: =IF(D16<>"",D16,N15) | O16: =M16&": "&N16 | P16: =IF(O16="","",IF(COUNTIF($O$1:O15,O16)=0,MAX($P$1:P15)+1,"")) | Q16: =IF(A16="","",COUNTIF($A$2:A16,A16)) | R16: =IF(A16="","",MAX($R$1:R15)+1)
A17: 46238 | B17: Tue | C17: web fix | D17: Convert file and folder to NextJS | E17: Convert the dashboard admin | F17: PRJ-3-KPI-3-ST-1 | G17: Development | H17: 0.63208333 | I17: 0.74508102 | J17: =IF(AND(H17<>"",I17<>""),(I17-H17)*24,"") | K17: feat: enforce starting subtask only if created + add subtask start command | L17: restroom(48m) | M17: =IF(C17<>"",C17,M16) | N17: =IF(D17<>"",D17,N16) | O17: =M17&": "&N17 | P17: =IF(O17="","",IF(COUNTIF($O$1:O16,O17)=0,MAX($P$1:P16)+1,"")) | Q17: =IF(A17="","",COUNTIF($A$2:A17,A17)) | R17: =IF(A17="","",MAX($R$1:R16)+1)
A18: 46239 | B18: Wed | C18: web fix | D18: Convert file and folder to NextJS | E18: update the dashboard | F18: PRJ-3-KPI-3-ST-2 | G18: Development | H18: 0.37601852 | I18: 0.46337963 | J18: =IF(AND(H18<>"",I18<>""),(I18-H18)*24,"") | K18: fix the tab bar in dashboard | M18: =IF(C18<>"",C18,M17) | N18: =IF(D18<>"",D18,N17) | O18: =M18&": "&N18 | P18: =IF(O18="","",IF(COUNTIF($O$1:O17,O18)=0,MAX($P$1:P17)+1,"")) | Q18: =IF(A18="","",COUNTIF($A$2:A18,A18)) | R18: =IF(A18="","",MAX($R$1:R17)+1)
A19: 46239 | B19: Wed | C19: web fix | D19: Fix the project web running correct | E19: update the authenticate | F19: PRJ-3-KPI-2-ST-2 | G19: Development | H19: 0.60953704 | I19: 0.37108796 | J19: =IF(AND(H19<>"",I19<>""),(I19-H19)*24,"") | K19: feat: enforce starting subtask only if created + add subtask start command | L19: personal(51m) | M19: =IF(C19<>"",C19,M18) | N19: =IF(D19<>"",D19,N18) | O19: =M19&": "&N19 | P19: =IF(O19="","",IF(COUNTIF($O$1:O18,O19)=0,MAX($P$1:P18)+1,"")) | Q19: =IF(A19="","",COUNTIF($A$2:A19,A19)) | R19: =IF(A19="","",MAX($R$1:R18)+1)
A20: 46239 | B20: Wed | C20: AI-Airtest | D20: Prompt AI | E20: improve prompt | F20: PRJ-1-KPI-2-ST-2 | G20: Development | H20: 0.60969907 | I20: 0.37126157 | J20: =IF(AND(H20<>"",I20<>""),(I20-H20)*24,"") | K20: cut off in code mcp | L20: personal(51m) | M20: =IF(C20<>"",C20,M19) | N20: =IF(D20<>"",D20,N19) | O20: =M20&": "&N20 | P20: =IF(O20="","",IF(COUNTIF($O$1:O19,O20)=0,MAX($P$1:P19)+1,"")) | Q20: =IF(A20="","",COUNTIF($A$2:A20,A20)) | R20: =IF(A20="","",MAX($R$1:R19)+1)
A21: 46240 | B21: Thu | C21: web fix | D21: Fix the project web running correct | E21: Add tab analystic in dashboard | F21: PRJ-3-KPI-2-ST-3 | G21: Development | H21: 0.56423611 | I21: 0.43835648 | J21: =IF(AND(H21<>"",I21<>""),(I21-H21)*24,"") | K21: feat: enforce starting subtask only if created + add subtask start command | L21: Break to rest in middle(141m) | M21: =IF(C21<>"",C21,M20) | N21: =IF(D21<>"",D21,N20) | O21: =M21&": "&N21 | P21: =IF(O21="","",IF(COUNTIF($O$1:O20,O21)=0,MAX($P$1:P20)+1,"")) | Q21: =IF(A21="","",COUNTIF($A$2:A21,A21)) | R21: =IF(A21="","",MAX($R$1:R20)+1)
A22: 46244 | B22: Mon | C22: AI-Airtest | D22: Prompt AI | E22: Fix the memory AI | F22: PRJ-1-KPI-2-ST-3 | G22: Development | H22: 0.29984954 | I22: 0.47297454 | J22: =IF(AND(H22<>"",I22<>""),(I22-H22)*24,"") | K22: feat: enforce starting subtask only if created + add subtask start command | L22: Out of token for the week(140m); Out of token for the week(5514m); use phone(0m) | M22: =IF(C22<>"",C22,M21) | N22: =IF(D22<>"",D22,N21) | O22: =M22&": "&N22 | P22: =IF(O22="","",IF(COUNTIF($O$1:O21,O22)=0,MAX($P$1:P21)+1,"")) | Q22: =IF(A22="","",COUNTIF($A$2:A22,A22)) | R22: =IF(A22="","",MAX($R$1:R21)+1)
A23: 46244 | B23: Mon | C23: web fix | D23: Convert file and folder to NextJS | E23: debug client | F23: PRJ-3-KPI-3-ST-3 | G23: Debug | H23: 0.10255787 | I23: 0.4733912 | J23: =IF(AND(H23<>"",I23<>""),(I23-H23)*24,"") | K23: Add breakpoint to debug the client | L23: off work(3833m); use phone(1m) | M23: =IF(C23<>"",C23,M22) | N23: =IF(D23<>"",D23,N22) | O23: =M23&": "&N23 | P23: =IF(O23="","",IF(COUNTIF($O$1:O22,O23)=0,MAX($P$1:P22)+1,"")) | Q23: =IF(A23="","",COUNTIF($A$2:A23,A23)) | R23: =IF(A23="","",MAX($R$1:R22)+1)
A24: 46244 | B24: Mon | C24: AI-Airtest | D24: Prompt AI | E24: coding MCP tree and file base | F24: PRJ-1-KPI-2-ST-4 | G24: Development | H24: 0.039872685 | I24: 0.47349537 | J24: =IF(AND(H24<>"",I24<>""),(I24-H24)*24,"") | K24: change the core MCP to lowest context | L24: end workday(921m); break(3945m) | M24: =IF(C24<>"",C24,M23) | N24: =IF(D24<>"",D24,N23) | O24: =M24&": "&N24 | P24: =IF(O24="","",IF(COUNTIF($O$1:O23,O24)=0,MAX($P$1:P23)+1,"")) | Q24: =IF(A24="","",COUNTIF($A$2:A24,A24)) | R24: =IF(A24="","",MAX($R$1:R23)+1)
A25: 46245 | B25: Tue | C25: web fix | D25: Fix the project web running correct | E25: finish admin function: [chapter, tag, slug, author] | F25: PRJ-3-KPI-2-ST-5 | G25: Development | H25: 0.41240741 | I25: 0.47821759 | J25: =IF(AND(H25<>"",I25<>""),(I25-H25)*24,"") | K25: Work completed | M25: =IF(C25<>"",C25,M24) | N25: =IF(D25<>"",D25,N24) | O25: =M25&": "&N25 | P25: =IF(O25="","",IF(COUNTIF($O$1:O24,O25)=0,MAX($P$1:P24)+1,"")) | Q25: =IF(A25="","",COUNTIF($A$2:A25,A25)) | R25: =IF(A25="","",MAX($R$1:R24)+1)
A26: 46245 | B26: Tue | C26: AI-Airtest | D26: Prompt AI | E26: change the MCP code base | F26: PRJ-1-KPI-2-ST-5 | G26: BUG | H26: 0.41259259 | I26: 0.4790162 | J26: =IF(AND(H26<>"",I26<>""),(I26-H26)*24,"") | K26: the prompt and folder structure hasbeen change, need to change the old code to correct and add missing in lib airtest | L26: review(108m); end of the day(989m) | M26: =IF(C26<>"",C26,M25) | N26: =IF(D26<>"",D26,N25) | O26: =M26&": "&N26 | P26: =IF(O26="","",IF(COUNTIF($O$1:O25,O26)=0,MAX($P$1:P25)+1,"")) | Q26: =IF(A26="","",COUNTIF($A$2:A26,A26)) | R26: =IF(A26="","",MAX($R$1:R25)+1)
A27: 46244 | B27: Mon | C27: AI-Airtest | D27: Fix the project web running correct | E27: sync with the server | F27: PRJ-3-KPI-2-ST-4 | G27: Development | H27: 0.47402778 | I27: 0.48064815 | J27: =IF(AND(H27<>"",I27<>""),(I27-H27)*24,"") | K27: Work completed | M27: =IF(C27<>"",C27,M26) | N27: =IF(D27<>"",D27,N26) | O27: =M27&": "&N27 | P27: =IF(O27="","",IF(COUNTIF($O$1:O26,O27)=0,MAX($P$1:P26)+1,"")) | Q27: =IF(A27="","",COUNTIF($A$2:A27,A27)) | R27: =IF(A27="","",MAX($R$1:R26)+1)
A28: 46246 | B28: Wed | C28: Comic web | D28: Admin dashboard update | E28: Update report bug analytics Sentry | F28: PRJ-5-KPI-2-ST-1 | G28: Dev | H28: 0.59283565 | I28: 0.59456019 | J28: =IF(AND(H28<>"",I28<>""),(I28-H28)*24,"") | K28: [HuyDD] Update the view and check in local to improve data view | M28: =IF(C28<>"",C28,M27) | N28: =IF(D28<>"",D28,N27) | O28: =M28&": "&N28 | P28: =IF(O28="","",IF(COUNTIF($O$1:O27,O28)=0,MAX($P$1:P27)+1,"")) | Q28: =IF(A28="","",COUNTIF($A$2:A28,A28)) | R28: =IF(A28="","",MAX($R$1:R27)+1)
A29: 46246 | B29: Wed | C29: Comic web | D29: Admin dashboard update | E29: Update report bug analytics Sentry | F29: PRJ-5-KPI-2-ST-1 | G29: Dev | H29: 0.47810185 | I29: 0.59482639 | J29: =IF(AND(H29<>"",I29<>""),(I29-H29)*24,"") | K29: [HuyDD] Update the view and check in local to improve data view | M29: =IF(C29<>"",C29,M28) | N29: =IF(D29<>"",D29,N28) | O29: =M29&": "&N29 | P29: =IF(O29="","",IF(COUNTIF($O$1:O28,O29)=0,MAX($P$1:P28)+1,"")) | Q29: =IF(A29="","",COUNTIF($A$2:A29,A29)) | R29: =IF(A29="","",MAX($R$1:R28)+1)
J30: =IF(AND(H30<>"",I30<>""),(I30-H30)*24,"") | M30: =IF(C30<>"",C30,M29) | N30: =IF(D30<>"",D30,N29) | O30: =M30&": "&N30 | P30: =IF(O30="","",IF(COUNTIF($O$1:O29,O30)=0,MAX($P$1:P29)+1,"")) | Q30: =IF(A30="","",COUNTIF($A$2:A30,A30)) | R30: =IF(A30="","",MAX($R$1:R29)+1)
J31: =IF(AND(H31<>"",I31<>""),(I31-H31)*24,"") | M31: =IF(C31<>"",C31,M30) | N31: =IF(D31<>"",D31,N30) | O31: =M31&": "&N31 | P31: =IF(O31="","",IF(COUNTIF($O$1:O30,O31)=0,MAX($P$1:P30)+1,"")) | Q31: =IF(A31="","",COUNTIF($A$2:A31,A31)) | R31: =IF(A31="","",MAX($R$1:R30)+1)
J32: =IF(AND(H32<>"",I32<>""),(I32-H32)*24,"") | M32: =IF(C32<>"",C32,M31) | N32: =IF(D32<>"",D32,N31) | O32: =M32&": "&N32 | P32: =IF(O32="","",IF(COUNTIF($O$1:O31,O32)=0,MAX($P$1:P31)+1,"")) | Q32: =IF(A32="","",COUNTIF($A$2:A32,A32)) | R32: =IF(A32="","",MAX($R$1:R31)+1)
J33: =IF(AND(H33<>"",I33<>""),(I33-H33)*24,"") | M33: =IF(C33<>"",C33,M32) | N33: =IF(D33<>"",D33,N32) | O33: =M33&": "&N33 | P33: =IF(O33="","",IF(COUNTIF($O$1:O32,O33)=0,MAX($P$1:P32)+1,"")) | Q33: =IF(A33="","",COUNTIF($A$2:A33,A33)) | R33: =IF(A33="","",MAX($R$1:R32)+1)
J34: =IF(AND(H34<>"",I34<>""),(I34-H34)*24,"") | M34: =IF(C34<>"",C34,M33) | N34: =IF(D34<>"",D34,N33) | O34: =M34&": "&N34 | P34: =IF(O34="","",IF(COUNTIF($O$1:O33,O34)=0,MAX($P$1:P33)+1,"")) | Q34: =IF(A34="","",COUNTIF($A$2:A34,A34)) | R34: =IF(A34="","",MAX($R$1:R33)+1)
J35: =IF(AND(H35<>"",I35<>""),(I35-H35)*24,"") | M35: =IF(C35<>"",C35,M34) | N35: =IF(D35<>"",D35,N34) | O35: =M35&": "&N35 | P35: =IF(O35="","",IF(COUNTIF($O$1:O34,O35)=0,MAX($P$1:P34)+1,"")) | Q35: =IF(A35="","",COUNTIF($A$2:A35,A35)) | R35: =IF(A35="","",MAX($R$1:R34)+1)
J36: =IF(AND(H36<>"",I36<>""),(I36-H36)*24,"") | M36: =IF(C36<>"",C36,M35) | N36: =IF(D36<>"",D36,N35) | O36: =M36&": "&N36 | P36: =IF(O36="","",IF(COUNTIF($O$1:O35,O36)=0,MAX($P$1:P35)+1,"")) | Q36: =IF(A36="","",COUNTIF($A$2:A36,A36)) | R36: =IF(A36="","",MAX($R$1:R35)+1)
J37: =IF(AND(H37<>"",I37<>""),(I37-H37)*24,"") | M37: =IF(C37<>"",C37,M36) | N37: =IF(D37<>"",D37,N36) | O37: =M37&": "&N37 | P37: =IF(O37="","",IF(COUNTIF($O$1:O36,O37)=0,MAX($P$1:P36)+1,"")) | Q37: =IF(A37="","",COUNTIF($A$2:A37,A37)) | R37: =IF(A37="","",MAX($R$1:R36)+1)
J38: =IF(AND(H38<>"",I38<>""),(I38-H38)*24,"") | M38: =IF(C38<>"",C38,M37) | N38: =IF(D38<>"",D38,N37) | O38: =M38&": "&N38 | P38: =IF(O38="","",IF(COUNTIF($O$1:O37,O38)=0,MAX($P$1:P37)+1,"")) | Q38: =IF(A38="","",COUNTIF($A$2:A38,A38)) | R38: =IF(A38="","",MAX($R$1:R37)+1)
J39: =IF(AND(H39<>"",I39<>""),(I39-H39)*24,"") | M39: =IF(C39<>"",C39,M38) | N39: =IF(D39<>"",D39,N38) | O39: =M39&": "&N39 | P39: =IF(O39="","",IF(COUNTIF($O$1:O38,O39)=0,MAX($P$1:P38)+1,"")) | Q39: =IF(A39="","",COUNTIF($A$2:A39,A39)) | R39: =IF(A39="","",MAX($R$1:R38)+1)
J40: =IF(AND(H40<>"",I40<>""),(I40-H40)*24,"") | M40: =IF(C40<>"",C40,M39) | N40: =IF(D40<>"",D40,N39) | O40: =M40&": "&N40 | P40: =IF(O40="","",IF(COUNTIF($O$1:O39,O40)=0,MAX($P$1:P39)+1,"")) | Q40: =IF(A40="","",COUNTIF($A$2:A40,A40)) | R40: =IF(A40="","",MAX($R$1:R39)+1)
...

Sheet Projects
A1: Code | B1: Project Name | C1: Description | D1: Status | E1: Created Date
A2: PRJ-1 | B2: AI-AutoTest | C2: Use AI to running autotesting | D2: Archived | E2: 46230
A3: PRJ-2 | B3: Test | C3: Testing gsheets sync | D3: Archived | E3: 46230
A4: PRJ-3 | B4: web fix | D4: Archived | E4: 46231
A5: PRJ-4 | B5: AI-Airtest | C5: Tạo automation test bằng ai với việc chỉ cần viết file .txt hoặc .md | D5: Archived | E5: 46232
A6: PRJ-5 | B6: Comic web | C6: Comic web for ads | D6: Active | E6: 46245
A7: PRJ-6 | B7: AI-test | C7: AI auto test by base airtest | D7: Active | E7: 46245

Sheet KPIs
A1: Code | B1: Father Task | C1: Project | D1: Date | E1: Deadline (days) | F1: Deadline (h) | G1: Status | H1: Completed Date | I1: Notes
A2: PRJ-1-KPI-1 | B2: Create MCP tool | C2: AI-AutoTest | D2: 46230 | E2: 7 | F2: =IF(E2<>"",E2*7.5,"") | G2: Done | H2: 46233
A3: PRJ-2-KPI-1 | B3: Test Feature | C3: Test | D3: 46230 | E3: 3 | F3: =IF(E3<>"",E3*7.5,"") | G3: Done | H3: 46233
A4: PRJ-3-KPI-1 | B4: Fix the error api not loadding | C4: web fix | D4: 46231 | E4: 2 | F4: =IF(E4<>"",E4*7.5,"") | G4: Done | H4: 46233
A5: PRJ-4-KPI-1 | B5: MCP-tool | C5: AI-Airtest | D5: 46232 | E5: 3 | F5: =IF(E5<>"",E5*7.5,"") | G5: Done | H5: 46233
A6: PRJ-3-KPI-2 | B6: Fix the project web running correct | C6: web fix | D6: 46232 | E6: 2 | F6: =IF(E6<>"",E6*7.5,"") | G6: Done | H6: 46245
A7: PRJ-1-KPI-2 | B7: Prompt AI | C7: AI-AutoTest | D7: 46233 | E7: 4 | F7: =IF(E7<>"",E7*7.5,"") | G7: Done | H7: 46245
A8: PRJ-3-KPI-3 | B8: Convert file and folder to NextJS | C8: web fix | D8: 46238 | E8: 3 | F8: =IF(E8<>"",E8*7.5,"") | G8: Done | H8: 46239
A9: PRJ-5-KPI-1 | B9: Push to production with function CRUD for chapter, author, comic, category, login oauth | C9: Comic web | D9: 46245 | E9: 2 | F9: =IF(E9<>"",E9*7.5,"") | G9: Done | H9: 46246
A10: PRJ-6-KPI-1 | B10: MCP base finish | C10: AI-test | D10: 46245 | E10: 3 | F10: =IF(E10<>"",E10*7.5,"") | G10: In Progress
A11: PRJ-5-KPI-2 | B11: Admin dashboard update | C11: Comic web | D11: 46246 | E11: 3 | F11: =IF(E11<>"",E11*7.5,"") | G11: In Progress
F12: =IF(E12<>"",E12*7.5,"")
F13: =IF(E13<>"",E13*7.5,"")
F14: =IF(E14<>"",E14*7.5,"")
F15: =IF(E15<>"",E15*7.5,"")
F16: =IF(E16<>"",E16*7.5,"")
F17: =IF(E17<>"",E17*7.5,"")
F18: =IF(E18<>"",E18*7.5,"")
F19: =IF(E19<>"",E19*7.5,"")
F20: =IF(E20<>"",E20*7.5,"")
F21: =IF(E21<>"",E21*7.5,"")
F22: =IF(E22<>"",E22*7.5,"")
F23: =IF(E23<>"",E23*7.5,"")
... F501: =IF(E501<>"",E501*7.5,"")

Sheet SubTasks
A1: Code | B1: Sub Task | C1: Father Task | D1: Project | E1: Status | F1: Created Date | G1: Completed Date | H1: Notes
A2: PRJ-1-KPI-1-ST-1 | B2: MCP log | C2: Create MCP tool | D2: AI-AutoTest | E2: Done | F2: 46230 | G2: 46231
A3: PRJ-1-KPI-1-ST-2 | B3: MCP call api | C3: Create MCP tool | D3: AI-AutoTest | E3: Done | F3: 46230 | G3: 46232
A4: PRJ-1-KPI-1-ST-3 | B4: MCP running test case | C4: Create MCP tool | D4: AI-AutoTest | E4: Done | F4: 46230 | G4: 46238
A5: PRJ-2-KPI-1-ST-1 | B5: Subtask 1 | C5: Test Feature | D5: Test | E5: Done | F5: 46230 | G5: 46231
A6: PRJ-2-KPI-1-ST-2 | B6: Subtask 2 | C6: Test Feature | D6: Test | E6: Done | F6: 46230 | G6: 46231
A7: PRJ-1-KPI-1-ST-4 | B7: fix MCP log and MCP game control | C7: Create MCP tool | D7: AI-AutoTest | E7: Done | F7: 46231 | G7: 46238
A8: PRJ-3-KPI-1-ST-1 | B8: Improve core code | C8: Fix the error api not loadding | D8: web | E8: Done | F8: 46231 | G8: 46231
A9: PRJ-1-KPI-1-ST-5 | B9: Fix MCP tool airtest | C9: Create MCP tool | D9: AI-Airtest | E9: Done | F9: 46232 | G9: 46238
A10: PRJ-3-KPI-2-ST-1 | B10: Running checker the UI/UX | C10: Fix the project web running correct | D10: web fix | E10: Done | F10: 46232 | G10: 46245
A11: PRJ-1-KPI-1-ST-6 | B11: Create MCP Airtest report | C11: Create MCP tool | D11: AI-AutoTest | E11: Done | F11: 46232 | G11: 46238
A12: PRJ-1-KPI-2-ST-1 | B12: Convert knowledge AI | C12: Prompt AI | D12: AI-AutoTest | E12: Done | F12: 46233 | G12: 46245
A13: PRJ-3-KPI-3-ST-1 | B13: Convert the dashboard admin | C13: Convert file and folder to NextJS | D13: web fix | E13: Done | F13: 46238 | G13: 46245
... A27: PRJ-5-KPI-2-ST-1 | B27: Update report bug analytics Sentry | C27: Admin dashboard update | D27: Comic web | E27: Done | F27: 46246 | G27: 46246
A28: PRJ-6-KPI-1-ST-2 | B28: Update the n8n running | C28: MCP base finish | D28: AI-test | E28: In Progress | F28: 46246
A29: PRJ-5-KPI-2-ST-2 | B29: Fix deploy local | C29: Admin dashboard update | D29: Comic web | E29: In Progress | F29: 46246

Sheet Weekly Summary
J1: LatestDate | K1: WeekStart | L1: WeekEnd
A2: ="Week: "&TEXT(K2,"dd-mm-yyyy")&" - "&TEXT(L2,"dd-mm-yyyy") | J2: =MAX('Time Entries'!A:A) | K2: =J2-WEEKDAY(J2,3) | L2: =J2+6
A4: Task | B4: Category | C4: =J2+0 | D4: =K2+1 | E4: =L2+2 | F4: =M2+3 | G4: =N2+4 | H4: =O2+5 | I4: =P2+6 | J4: Total | O4: =K2+0 | P4: =K2+1 | Q4: =K2+2 | R4: =K2+3 | S4: =K2+4 | T4: =K2+5 | U4: =K2+6
A5: =IFERROR(INDEX('Time Entries'!$O:$O,MATCH(ROW()-4,'Time Entries'!$P:$P,0)),"") | B5: =IF($A5="","",IFERROR(INDEX('Time Entries'!G:G,MATCH($A5,'Time Entries'!$O:$O,0)),"")) | C5: =IF($A5="","",SUMIFS('Time Entries'!J:J,'Time Entries'!O:O,$A5,'Time Entries'!A:A,$O$4+0)) | D5: =IF($A5="","",SUMIFS('Time Entries'!J:J,'Time Entries'!O:O,$A5,'Time Entries'!A:A,$O$4+1)) | E5: =IF($A5="","",SUMIFS('Time Entries'!J:J,'Time Entries'!O:O,$A5,'Time Entries'!A:A,$O$4+2)) | F5: =IF($A5="","",SUMIFS('Time Entries'!J:J,'Time Entries'!O:O,$A5,'Time Entries'!A:A,$O$4+3)) | G5: =IF($A5="","",SUMIFS('Time Entries'!J:J,'Time Entries'!O:O,$A5,'Time Entries'!A:A,$O$4+4)) | H5: =IF($A5="","",SUMIFS('Time Entries'!J:J,'Time Entries'!O:O,$A5,'Time Entries'!A:A,$O$4+5)) | I5: =IF($A5="","",SUMIFS('Time Entries'!J:J,'Time Entries'!O:O,$A5,'Time Entries'!A:A,$O$4+6)) | J5: =IF($A5="","",SUM(C5:I5))
A6: =IFERROR(INDEX('Time Entries'!$O:$O,MATCH(ROW()-4,'Time Entries'!$P:$P,0)),"") | B6: =IF($A6="","",IFERROR(INDEX('Time Entries'!G:G,MATCH($A6,'Time Entries'!$O:$O,0)),"")) | C6: =IF($A6="","",SUMIFS('Time Entries'!J:J,'Time Entries'!O:O,$A6,'Time Entries'!A:A,$O$4+0)) | D6: =IF($A6="","",SUMIFS('Time Entries'!J:J,'Time Entries'!O:O,$A6,'Time Entries'!A:A,$O$4+1)) | E6: =IF($A6="","",SUMIFS('Time Entries'!J:J,'Time Entries'!O:O,$A6,'Time Entries'!A:A,$O$4+2)) | F6: =IF($A6="","",SUMIFS('Time Entries'!J:J,'Time Entries'!O:O,$A6,'Time Entries'!A:A,$O$4+3)) | G6: =IF($A6="","",SUMIFS('Time Entries'!J:J,'Time Entries'!O:O,$A6,'Time Entries'!A:A,$O$4+4)) | H6: =IF($A6="","",SUMIFS('Time Entries'!J:J,'Time Entries'!O:O,$A6,'Time Entries'!A:A,$O$4+5)) | I6: =IF($A6="","",SUMIFS('Time Entries'!J:J,'Time Entries'!O:O,$A6,'Time Entries'!A:A,$O$4+6)) | J6: =IF($A6="","",SUM(C6:I6))
A7: =IFERROR(INDEX('Time Entries'!$O:$O,MATCH(ROW()-4,'Time Entries'!$P:$P,0)),"") | B7: =IF($A7="","",IFERROR(INDEX('Time Entries'!G:G,MATCH($A7,'Time Entries'!$O:$O,0)),"")) | C7: =IF($A7="","",SUMIFS('Time Entries'!J:J,'Time Entries'!O:O,$A7,'Time Entries'!A:A,$O$4+0)) | D7: =IF($A7="","",SUMIFS('Time Entries'!J:J,'Time Entries'!O:O,$A7,'Time Entries'!A:A,$O$4+1)) | E7: =IF($A7="","",SUMIFS('Time Entries'!J:J,'Time Entries'!O:O,$A7,'Time Entries'!A:A,$O$4+2)) | F7: =IF($A7="","",SUMIFS('Time Entries'!J:J,'Time Entries'!O:O,$A7,'Time Entries'!A:A,$O$4+3)) | G7: =IF($A7="","",SUMIFS('Time Entries'!J:J,'Time Entries'!O:O,$A7,'Time Entries'!A:A,$O$4+4)) | H7: =IF($A7="","",SUMIFS('Time Entries'!J:J,'Time Entries'!O:O,$A7,'Time Entries'!A:A,$O$4+5)) | I7: =IF($A7="","",SUMIFS('Time Entries'!J:J,'Time Entries'!O:O,$A7,'Time Entries'!A:A,$O$4+6)) | J7: =IF($A7="","",SUM(C7:I7))
A8: =IFERROR(INDEX('Time Entries'!$O:$O,MATCH(ROW()-4,'Time Entries'!$P:$P,0)),"") | B8: =IF($A8="","",IFERROR(INDEX('Time Entries'!G:G,MATCH($A8,'Time Entries'!$O:$O,0)),"")) | C8: =IF($A8="","",SUMIFS('Time Entries'!J:J,'Time Entries'!O:O,$A8,'Time Entries'!A:A,$O$4+0)) | D8: =IF($A8="","",SUMIFS('Time Entries'!J:J,'Time Entries'!O:O,$A8,'Time Entries'!A:A,$O$4+1)) | E8: =IF($A8="","",SUMIFS('Time Entries'!J:J,'Time Entries'!O:O,$A8,'Time Entries'!A:A,$O$4+2)) | F8: =IF($A8="","",SUMIFS('Time Entries'!J:J,'Time Entries'!O:O,$A8,'Time Entries'!A:A,$O$4+3)) | G8: =IF($A8="","",SUMIFS('Time Entries'!J:J,'Time Entries'!O:O,$A8,'Time Entries'!A:A,$O$4+4)) | H8: =IF($A8="","",SUMIFS('Time Entries'!J:J,'Time Entries'!O:O,$A8,'Time Entries'!A:A,$O$4+5)) | I8: =IF($A8="","",SUMIFS('Time Entries'!J:J,'Time Entries'!O:O,$A8,'Time Entries'!A:A,$O$4+6)) | J8: =IF($A8="","",SUM(C8:I8))
A9: =IFERROR(INDEX('Time Entries'!$O:$O,MATCH(ROW()-4,'Time Entries'!$P:$P,0)),"") | B9: =IF($A9="","",IFERROR(INDEX('Time Entries'!G:G,MATCH($A9,'Time Entries'!$O:$O,0)),"")) | C9: =IF($A9="","",SUMIFS('Time Entries'!J:J,'Time Entries'!O:O,$A9,'Time Entries'!A:A,$O$4+0)) | D9: =IF($A9="","",SUMIFS('Time Entries'!J:J,'Time Entries'!O:O,$A9,'Time Entries'!A:A,$O$4+1)) | E9: =IF($A9="","",SUMIFS('Time Entries'!J:J,'Time Entries'!O:O,$A9,'Time Entries'!A:A,$O$4+2)) | F9: =IF($A9="","",SUMIFS('Time Entries'!J:J,'Time Entries'!O:O,$A9,'Time Entries'!A:A,$O$4+3)) | G9: =IF($A9="","",SUMIFS('Time Entries'!J:J,'Time Entries'!O:O,$A9,'Time Entries'!A:A,$O$4+4)) | H9: =IF($A9="","",SUMIFS('Time Entries'!J:J,'Time Entries'!O:O,$A9,'Time Entries'!A:A,$O$4+5)) | I9: =IF($A9="","",SUMIFS('Time Entries'!J:J,'Time Entries'!O:O,$A9,'Time Entries'!A:A,$O$4+6)) | J9: =IF($A9="","",SUM(C9:I9))
A10: =IFERROR(INDEX('Time Entries'!$O:$O,MATCH(ROW()-4,'Time Entries'!$P:$P,0)),"") | B10: =IF($A10="","",IFERROR(INDEX('Time Entries'!G:G,MATCH($A10,'Time Entries'!$O:$O,0)),"")) | C10: =IF($A10="","",SUMIFS('Time Entries'!J:J,'Time Entries'!O:O,$A10,'Time Entries'!A:A,$O$4+0)) | D10: =IF($A10="","",SUMIFS('Time Entries'!J:J,'Time Entries'!O:O,$A10,'Time Entries'!A:A,$O$4+1)) | E10: =IF($A10="","",SUMIFS('Time Entries'!J:J,'Time Entries'!O:O,$A10,'Time Entries'!A:A,$O$4+2)) | F10: =IF($A10="","",SUMIFS('Time Entries'!J:J,'Time Entries'!O:O,$A10,'Time Entries'!A:A,$O$4+3)) | G10: =IF($A10="","",SUMIFS('Time Entries'!J:J,'Time Entries'!O:O,$A10,'Time Entries'!A:A,$O$4+4)) | H10: =IF($A10="","",SUMIFS('Time Entries'!J:J,'Time Entries'!O:O,$A10,'Time Entries'!A:A,$O$4+5)) | I10: =IF($A10="","",SUMIFS('Time Entries'!J:J,'Time Entries'!O:O,$A10,'Time Entries'!A:A,$O$4+6)) | J10: =IF($A10="","",SUM(C10:I10))
A11: =IFERROR(INDEX('Time Entries'!$O:$O,MATCH(ROW()-4,'Time Entries'!$P:$P,0)),"") | B11: =IF($A11="","",IFERROR(INDEX('Time Entries'!G:G,MATCH($A11,'Time Entries'!$O:$O,0)),"")) | C11: =IF($A11="","",SUMIFS('Time Entries'!J:J,'Time Entries'!O:O,$A11,'Time Entries'!A:A,$O$4+0)) | D11: =IF($A11="","",SUMIFS('Time Entries'!J:J,'Time Entries'!O:O,$A11,'Time Entries'!A:A,$O$4+1)) | E11: =IF($A11="","",SUMIFS('Time Entries'!J:J,'Time Entries'!O:O,$A11,'Time Entries'!A:A,$O$4+2)) | F11: =IF($A11="","",SUMIFS('Time Entries'!J:J,'Time Entries'!O:O,$A11,'Time Entries'!A:A,$O$4+3)) | G11: =IF($A11="","",SUMIFS('Time Entries'!J:J,'Time Entries'!O:O,$A11,'Time Entries'!A:A,$O$4+4)) | H11: =IF($A11="","",SUMIFS('Time Entries'!J:J,'Time Entries'!O:O,$A11,'Time Entries'!A:A,$O$4+5)) | I11: =IF($A11="","",SUMIFS('Time Entries'!J:J,'Time Entries'!O:O,$A11,'Time Entries'!A:A,$O$4+6)) | J11: =IF($A11="","",SUM(C11:I11))
A12: =IFERROR(INDEX('Time Entries'!$O:$O,MATCH(ROW()-4,'Time Entries'!$P:$P,0)),"") | B12: =IF($A12="","",IFERROR(INDEX('Time Entries'!G:G,MATCH($A12,'Time Entries'!$O:$O,0)),"")) | C12: =IF($A12="","",SUMIFS('Time Entries'!J:J,'Time Entries'!O:O,$A12,'Time Entries'!A:A,$O$4+0)) | D12: =IF($A12="","",SUMIFS('Time Entries'!J:J,'Time Entries'!O:O,$A12,'Time Entries'!A:A,$O$4+1)) | E12: =IF($A12="","",SUMIFS('Time Entries'!J:J,'Time Entries'!O:O,$A12,'Time Entries'!A:A,$O$4+2)) | F12: =IF($A12="","",SUMIFS('Time Entries'!J:J,'Time Entries'!O:O,$A12,'Time Entries'!A:A,$O$4+3)) | G12: =IF($A12="","",SUMIFS('Time Entries'!J:J,'Time Entries'!O:O,$A12,'Time Entries'!A:A,$O$4+4)) | H12: =IF($A12="","",SUMIFS('Time Entries'!J:J,'Time Entries'!O:O,$A12,'Time Entries'!A:A,$O$4+5)) | I12: =IF($A12="","",SUMIFS('Time Entries'!J:J,'Time Entries'!O:O,$A12,'Time Entries'!A:A,$O$4+6)) | J12: =IF($A12="","",SUM(C12:I12))
A13: =IFERROR(INDEX('Time Entries'!$O:$O,MATCH(ROW()-4,'Time Entries'!$P:$P,0)),"") | B13: =IF($A13="","",IFERROR(INDEX('Time Entries'!G:G,MATCH($A13,'Time Entries'!$O:$O,0)),"")) | C13: =IF($A13="","",SUMIFS('Time Entries'!J:J,'Time Entries'!O:O,$A13,'Time Entries'!A:A,$O$4+0)) | D13: =IF($A13="","",SUMIFS('Time Entries'!J:J,'Time Entries'!O:O,$A13,'Time Entries'!A:A,$O$4+1)) | E13: =IF($A13="","",SUMIFS('Time Entries'!J:J,'Time Entries'!O:O,$A13,'Time Entries'!A:A,$O$4+2)) | F13: =IF($A13="","",SUMIFS('Time Entries'!J:J,'Time Entries'!O:O,$A13,'Time Entries'!A:A,$O$4+3)) | G13: =IF($A13="","",SUMIFS('Time Entries'!J:J,'Time Entries'!O:O,$A13,'Time Entries'!A:A,$O$4+4)) | H13: =IF($A13="","",SUMIFS('Time Entries'!J:J,'Time Entries'!O:O,$A13,'Time Entries'!A:A,$O$4+5)) | I13: =IF($A13="","",SUMIFS('Time Entries'!J:J,'Time Entries'!O:O,$A13,'Time Entries'!A:A,$O$4+6)) | J13: =IF($A13="","",SUM(C13:I13))
A14: =IFERROR(INDEX('Time Entries'!$O:$O,MATCH(ROW()-4,'Time Entries'!$P:$P,0)),"") | B14: =IF($A14="","",IFERROR(INDEX('Time Entries'!G:G,MATCH($A14,'Time Entries'!$O:$O,0)),"")) | C14: =IF($A14="","",SUMIFS('Time Entries'!J:J,'Time Entries'!O:O,$A14,'Time Entries'!A:A,$O$4+0)) | D14: =IF($A14="","",SUMIFS('Time Entries'!J:J,'Time Entries'!O:O,$A14,'Time Entries'!A:A,$O$4+1)) | E14: =IF($A14="","",SUMIFS('Time Entries'!J:J,'Time Entries'!O:O,$A14,'Time Entries'!A:A,$O$4+2)) | F14: =IF($A14="","",SUMIFS('Time Entries'!J:J,'Time Entries'!O:O,$A14,'Time Entries'!A:A,$O$4+3)) | G14: =IF($A14="","",SUMIFS('Time Entries'!J:J,'Time Entries'!O:O,$A14,'Time Entries'!A:A,$O$4+4)) | H14: =IF($A14="","",SUMIFS('Time Entries'!J:J,'Time Entries'!O:O,$A14,'Time Entries'!A:A,$O$4+5)) | I14: =IF($A14="","",SUMIFS('Time Entries'!J:J,'Time Entries'!O:O,$A14,'Time Entries'!A:A,$O$4+6)) | J14: =IF($A14="","",SUM(C14:I14))
A15: =IFERROR(INDEX('Time Entries'!$O:$O,MATCH(ROW()-4,'Time Entries'!$P:$P,0)),"") | B15: =IF($A15="","",IFERROR(INDEX('Time Entries'!G:G,MATCH($A15,'Time Entries'!$O:$O,0)),"")) | C15: =IF($A15="","",SUMIFS('Time Entries'!J:J,'Time Entries'!O:O,$A15,'Time Entries'!A:A,$O$4+0)) | D15: =IF($A15="","",SUMIFS('Time Entries'!J:J,'Time Entries'!O:O,$A15,'Time Entries'!A:A,$O$4+1)) | E15: =IF($A15="","",SUMIFS('Time Entries'!J:J,'Time Entries'!O:O,$A15,'Time Entries'!A:A,$O$4+2)) | F15: =IF($A15="","",SUMIFS('Time Entries'!J:J,'Time Entries'!O:O,$A15,'Time Entries'!A:A,$O$4+3)) | G15: =IF($A15="","",SUMIFS('Time Entries'!J:J,'Time Entries'!O:O,$A15,'Time Entries'!A:A,$O$4+4)) | H15: =IF($A15="","",SUMIFS('Time Entries'!J:J,'Time Entries'!O:O,$A15,'Time Entries'!A:A,$O$4+5)) | I15: =IF($A15="","",SUMIFS('Time Entries'!J:J,'Time Entries'!O:O,$A15,'Time Entries'!A:A,$O$4+6)) | J15: =IF($A15="","",SUM(C15:I15))
A16: =IFERROR(INDEX('Time Entries'!$O:$O,MATCH(ROW()-4,'Time Entries'!$P:$P,0)),"") | B16: =IF($A16="","",IFERROR(INDEX('Time Entries'!G:G,MATCH($A16,'Time Entries'!$O:$O,0)),"")) | C16: =IF($A16="","",SUMIFS('Time Entries'!J:J,'Time Entries'!O:O,$A16,'Time Entries'!A:A,$O$4+0)) | D16: =IF($A16="","",SUMIFS('Time Entries'!J:J,'Time Entries'!O:O,$A16,'Time Entries'!A:A,$O$4+1)) | E16: =IF($A16="","",SUMIFS('Time Entries'!J:J,'Time Entries'!O:O,$A16,'Time Entries'!A:A,$O$4+2)) | F16: =IF($A16="","",SUMIFS('Time Entries'!J:J,'Time Entries'!O:O,$A16,'Time Entries'!A:A,$O$4+3)) | G16: =IF($A16="","",SUMIFS('Time Entries'!J:J,'Time Entries'!O:O,$A16,'Time Entries'!A:A,$O$4+4)) | H16: =IF($A16="","",SUMIFS('Time Entries'!J:J,'Time Entries'!O:O,$A16,'Time Entries'!A:A,$O$4+5)) | I16: =IF($A16="","",SUMIFS('Time Entries'!J:J,'Time Entries'!O:O,$A16,'Time Entries'!A:A,$O$4+6)) | J16: =IF($A16="","",SUM(C16:I16))
... A64: =IFERROR(INDEX('Time Entries'!$O:$O,MATCH(ROW()-4,'Time Entries'!$P:$P,0)),"") | B64: =IF($A64="","",IFERROR(INDEX('Time Entries'!G:G,MATCH($A64,'Time Entries'!$O:$O,0)),"")) | C64: =IF($A64="","",SUMIFS('Time Entries'!J:J,'Time Entries'!O:O,$A64,'Time Entries'!A:A,$O$4+0)) | D64: =IF($A64="","",SUMIFS('Time Entries'!J:J,'Time Entries'!O:O,$A64,'Time Entries'!A:A,$O$4+1)) | E64: =IF($A64="","",SUMIFS('Time Entries'!J:J,'Time Entries'!O:O,$A64,'Time Entries'!A:A,$O$4+2)) | F64: =IF($A64="","",SUMIFS('Time Entries'!J:J,'Time Entries'!O:O,$A64,'Time Entries'!A:A,$O$4+3)) | G64: =IF($A64="","",SUMIFS('Time Entries'!J:J,'Time Entries'!O:O,$A64,'Time Entries'!A:A,$O$4+4)) | H64: =IF($A64="","",SUMIFS('Time Entries'!J:J,'Time Entries'!O:O,$A64,'Time Entries'!A:A,$O$4+5)) | I64: =IF($A64="","",SUMIFS('Time Entries'!J:J,'Time Entries'!O:O,$A64,'Time Entries'!A:A,$O$4+6)) | J64: =IF($A64="","",SUM(C64:I64))
A66: GRAND TOTAL | C66: =SUM(C5:C64) | D66: =SUM(D5:D64) | E66: =SUM(E5:E64) | F66: =SUM(F5:F64) | G66: =SUM(G5:G64) | H66: =SUM(H5:H64) | I66: =SUM(I5:I64) | J66: =SUM(J5:J64) | K66: =SUM(K5:K64)

Sheet Daily Detail
A1: Daily Detail | C1: =MAX('Time Entries'!A:A) | D1: (Edit C1 to change date)
A2: =TEXT(C1,"dd-mm-yyyy")
A3: Time Range | B3: Project | C3: Father Task | D3: Sub Task Code | E3: Category | F3: Duration (h) | G3: Description
A4: =IF($H4="","",IF(INDEX('Time Entries'!G:G,$H4)="","",INDEX('Time Entries'!G:G,$H4)&" - "&INDEX('Time Entries'!H:H,$H4))) | B4: =IF($H4="","",IF(INDEX('Time Entries'!G:G,$H4)="","",INDEX('Time Entries'!M:M,$H4))) | C4: =IF($H4="","",IF(INDEX('Time Entries'!G:G,$H4)="","",INDEX('Time Entries'!N:N,$H4))) | D4: =IF($H4="","",IF(INDEX('Time Entries'!G:G,$H4)="","",INDEX('Time Entries'!F:F,$H4))) | E4: =IF($H4="","",IF(INDEX('Time Entries'!G:G,$H4)="","",INDEX('Time Entries'!G:G,$H4))) | F4: =IF($H4="","",IF(INDEX('Time Entries'!G:G,$H4)="","",INDEX('Time Entries'!J:J,$H4))) | G4: =IF($H4="","",IF(INDEX('Time Entries'!G:G,$H4)="","",INDEX('Time Entries'!K:K,$H4))) | H4: =IFERROR(MATCH($C$1,'Time Entries'!A:A,0),"") | I4: =IFERROR(COUNTIF('Time Entries'!A:A,$C$1),"")
A5: =IF($H5="","",IF(INDEX('Time Entries'!G:G,$H5)="","",INDEX('Time Entries'!G:G,$H5)&" - "&INDEX('Time Entries'!H:H,$H5))) | B5: =IF($H5="","",IF(INDEX('Time Entries'!G:G,$H5)="","",INDEX('Time Entries'!M:M,$H5))) | C5: =IF($H5="","",IF(INDEX('Time Entries'!G:G,$H5)="","",INDEX('Time Entries'!N:N,$H5))) | D5: =IF($H5="","",IF(INDEX('Time Entries'!G:G,$H5)="","",INDEX('Time Entries'!F:F,$H5))) | E5: =IF($H5="","",IF(INDEX('Time Entries'!G:G,$H5)="","",INDEX('Time Entries'!G:G,$H5))) | F5: =IF($H5="","",IF(INDEX('Time Entries'!G:G,$H5)="","",INDEX('Time Entries'!J:J,$H5))) | G5: =IF($H5="","",IF(INDEX('Time Entries'!G:G,$H5)="","",INDEX('Time Entries'!K:K,$H5))) | H5: =IF(AND($I$4>=ROW()-3,$H$4<>""),$H$4+ROW()-4,"")
A6: =IF($H6="","",IF(INDEX('Time Entries'!G:G,$H6)="","",INDEX('Time Entries'!G:G,$H6)&" - "&INDEX('Time Entries'!H:H,$H6))) | B6: =IF($H6="","",IF(INDEX('Time Entries'!G:G,$H6)="","",INDEX('Time Entries'!M:M,$H6))) | C6: =IF($H6="","",IF(INDEX('Time Entries'!G:G,$H6)="","",INDEX('Time Entries'!N:N,$H6))) | D6: =IF($H6="","",IF(INDEX('Time Entries'!G:G,$H6)="","",INDEX('Time Entries'!F:F,$H6))) | E6: =IF($H6="","",IF(INDEX('Time Entries'!G:G,$H6)="","",INDEX('Time Entries'!G:G,$H6))) | F6: =IF($H6="","",IF(INDEX('Time Entries'!G:G,$H6)="","",INDEX('Time Entries'!J:J,$H6))) | G6: =IF($H6="","",IF(INDEX('Time Entries'!G:G,$H6)="","",INDEX('Time Entries'!K:K,$H6))) | H6: =IF(AND($I$4>=ROW()-3,$H$4<>""),$H$4+ROW()-4,"")
A7: =IF($H7="","",IF(INDEX('Time Entries'!G:G,$H7)="","",INDEX('Time Entries'!G:G,$H7)&" - "&INDEX('Time Entries'!H:H,$H7))) | B7: =IF($H7="","",IF(INDEX('Time Entries'!G:G,$H7)="","",INDEX('Time Entries'!M:M,$H7))) | C7: =IF($H7="","",IF(INDEX('Time Entries'!G:G,$H7)="","",INDEX('Time Entries'!N:N,$H7))) | D7: =IF($H7="","",IF(INDEX('Time Entries'!G:G,$H7)="","",INDEX('Time Entries'!F:F,$H7))) | E7: =IF($H7="","",IF(INDEX('Time Entries'!G:G,$H7)="","",INDEX('Time Entries'!G:G,$H7))) | F7: =IF($H7="","",IF(INDEX('Time Entries'!G:G,$H7)="","",INDEX('Time Entries'!J:J,$H7))) | G7: =IF($H7="","",IF(INDEX('Time Entries'!G:G,$H7)="","",INDEX('Time Entries'!K:K,$H7))) | H7: =IF(AND($I$4>=ROW()-3,$H$4<>""),$H$4+ROW()-4,"")
A8: =IF($H8="","",IF(INDEX('Time Entries'!G:G,$H8)="","",INDEX('Time Entries'!G:G,$H8)&" - "&INDEX('Time Entries'!H:H,$H8))) | B8: =IF($H8="","",IF(INDEX('Time Entries'!G:G,$H8)="","",INDEX('Time Entries'!M:M,$H8))) | C8: =IF($H8="","",IF(INDEX('Time Entries'!G:G,$H8)="","",INDEX('Time Entries'!N:N,$H8))) | D8: =IF($H8="","",IF(INDEX('Time Entries'!G:G,$H8)="","",INDEX('Time Entries'!F:F,$H8))) | E8: =IF($H8="","",IF(INDEX('Time Entries'!G:G,$H8)="","",INDEX('Time Entries'!G:G,$H8))) | F8: =IF($H8="","",IF(INDEX('Time Entries'!G:G,$H8)="","",INDEX('Time Entries'!J:J,$H8))) | G8: =IF($H8="","",IF(INDEX('Time Entries'!G:G,$H8)="","",INDEX('Time Entries'!K:K,$H8))) | H8: =IF(AND($I$4>=ROW()-3,$H$4<>""),$H$4+ROW()-4,"")
A9: =IF($H9="","",IF(INDEX('Time Entries'!G:G,$H9)="","",INDEX('Time Entries'!G:G,$H9)&" - "&INDEX('Time Entries'!H:H,$H9))) | B9: =IF($H9="","",IF(INDEX('Time Entries'!G:G,$H9)="","",INDEX('Time Entries'!M:M,$H9))) | C9: =IF($H9="","",IF(INDEX('Time Entries'!G:G,$H9)="","",INDEX('Time Entries'!N:N,$H9))) | D9: =IF($H9="","",IF(INDEX('Time Entries'!G:G,$H9)="","",INDEX('Time Entries'!F:F,$H9))) | E9: =IF($H9="","",IF(INDEX('Time Entries'!G:G,$H9)="","",INDEX('Time Entries'!G:G,$H9))) | F9: =IF($H9="","",IF(INDEX('Time Entries'!G:G,$H9)="","",INDEX('Time Entries'!J:J,$H9))) | G9: =IF($H9="","",IF(INDEX('Time Entries'!G:G,$H9)="","",INDEX('Time Entries'!K:K,$H9))) | H9: =IF(AND($I$4>=ROW()-3,$H$4<>""),$H$4+ROW()-4,"")
A10: =IF($H10="","",IF(INDEX('Time Entries'!G:G,$H10)="","",INDEX('Time Entries'!G:G,$H10)&" - "&INDEX('Time Entries'!H:H,$H10))) | B10: =IF($H10="","",IF(INDEX('Time Entries'!G:G,$H10)="","",INDEX('Time Entries'!M:M,$H10))) | C10: =IF($H10="","",IF(INDEX('Time Entries'!G:G,$H10)="","",INDEX('Time Entries'!N:N,$H10))) | D10: =IF($H10="","",IF(INDEX('Time Entries'!G:G,$H10)="","",INDEX('Time Entries'!F:F,$H10))) | E10: =IF($H10="","",IF(INDEX('Time Entries'!G:G,$H10)="","",INDEX('Time Entries'!G:G,$H10))) | F10: =IF($H10="","",IF(INDEX('Time Entries'!G:G,$H10)="","",INDEX('Time Entries'!J:J,$H10))) | G10: =IF($H10="","",IF(INDEX('Time Entries'!G:G,$H10)="","",INDEX('Time Entries'!K:K,$H10))) | H10: =IF(AND($I$4>=ROW()-3,$H$4<>""),$H$4+ROW()-4,"")
A11: =IF($H11="","",IF(INDEX('Time Entries'!G:G,$H11)="","",INDEX('Time Entries'!G:G,$H11)&" - "&INDEX('Time Entries'!H:H,$H11))) | B11: =IF($H11="","",IF(INDEX('Time Entries'!G:G,$H11)="","",INDEX('Time Entries'!M:M,$H11))) | C11: =IF($H11="","",IF(INDEX('Time Entries'!G:G,$H11)="","",INDEX('Time Entries'!N:N,$H11))) | D11: =IF($H11="","",IF(INDEX('Time Entries'!G:G,$H11)="","",INDEX('Time Entries'!F:F,$H11))) | E11: =IF($H11="","",IF(INDEX('Time Entries'!G:G,$H11)="","",INDEX('Time Entries'!G:G,$H11))) | F11: =IF($H11="","",IF(INDEX('Time Entries'!G:G,$H11)="","",INDEX('Time Entries'!J:J,$H11))) | G11: =IF($H11="","",IF(INDEX('Time Entries'!G:G,$H11)="","",INDEX('Time Entries'!K:K,$H11))) | H11: =IF(AND($I$4>=ROW()-3,$H$4<>""),$H$4+ROW()-4,"")
A12: =IF($H12="","",IF(INDEX('Time Entries'!G:G,$H12)="","",INDEX('Time Entries'!G:G,$H12)&" - "&INDEX('Time Entries'!H:H,$H12))) | B12: =IF($H12="","",IF(INDEX('Time Entries'!G:G,$H12)="","",INDEX('Time Entries'!M:M,$H12))) | C12: =IF($H12="","",IF(INDEX('Time Entries'!G:G,$H12)="","",INDEX('Time Entries'!N:N,$H12))) | D12: =IF($H12="","",IF(INDEX('Time Entries'!G:G,$H12)="","",INDEX('Time Entries'!F:F,$H12))) | E12: =IF($H12="","",IF(INDEX('Time Entries'!G:G,$H12)="","",INDEX('Time Entries'!G:G,$H12))) | F12: =IF($H12="","",IF(INDEX('Time Entries'!G:G,$H12)="","",INDEX('Time Entries'!J:J,$H12))) | G12: =IF($H12="","",IF(INDEX('Time Entries'!G:G,$H12)="","",INDEX('Time Entries'!K:K,$H12))) | H12: =IF(AND($I$4>=ROW()-3,$H$4<>""),$H$4+ROW()-4,"")
A13: =IF($H13="","",IF(INDEX('Time Entries'!G:G,$H13)="","",INDEX('Time Entries'!G:G,$H13)&" - "&INDEX('Time Entries'!H:H,$H13))) | B13: =IF($H13="","",IF(INDEX('Time Entries'!G:G,$H13)="","",INDEX('Time Entries'!M:M,$H13))) | C13: =IF($H13="","",IF(INDEX('Time Entries'!G:G,$H13)="","",INDEX('Time Entries'!N:N,$H13))) | D13: =IF($H13="","",IF(INDEX('Time Entries'!G:G,$H13)="","",INDEX('Time Entries'!F:F,$H13))) | E13: =IF($H13="","",IF(INDEX('Time Entries'!G:G,$H13)="","",INDEX('Time Entries'!G:G,$H13))) | F13: =IF($H13="","",IF(INDEX('Time Entries'!G:G,$H13)="","",INDEX('Time Entries'!J:J,$H13))) | G13: =IF($H13="","",IF(INDEX('Time Entries'!G:G,$H13)="","",INDEX('Time Entries'!K:K,$H13))) | H13: =IF(AND($I$4>=ROW()-3,$H$4<>""),$H$4+ROW()-4,"")
A14: =IF($H14="","",IF(INDEX('Time Entries'!G:G,$H14)="","",INDEX('Time Entries'!G:G,$H14)&" - "&INDEX('Time Entries'!H:H,$H14))) | B14: =IF($H14="","",IF(INDEX('Time Entries'!G:G,$H14)="","",INDEX('Time Entries'!M:M,$H14))) | C14: =IF($H14="","",IF(INDEX('Time Entries'!G:G,$H14)="","",INDEX('Time Entries'!N:N,$H14))) | D14: =IF($H14="","",IF(INDEX('Time Entries'!G:G,$H14)="","",INDEX('Time Entries'!F:F,$H14))) | E14: =IF($H14="","",IF(INDEX('Time Entries'!G:G,$H14)="","",INDEX('Time Entries'!G:G,$H14))) | F14: =IF($H14="","",IF(INDEX('Time Entries'!G:G,$H14)="","",INDEX('Time Entries'!J:J,$H14))) | G14: =IF($H14="","",IF(INDEX('Time Entries'!G:G,$H14)="","",INDEX('Time Entries'!K:K,$H14))) | H14: =IF(AND($I$4>=ROW()-3,$H$4<>""),$H$4+ROW()-4,"")
A15: =IF($H15="","",IF(INDEX('Time Entries'!G:G,$H15)="","",INDEX('Time Entries'!G:G,$H15)&" - "&INDEX('Time Entries'!H:H,$H15))) | B15: =IF($H15="","",IF(INDEX('Time Entries'!G:G,$H15)="","",INDEX('Time Entries'!M:M,$H15))) | C15: =IF($H15="","",IF(INDEX('Time Entries'!G:G,$H15)="","",INDEX('Time Entries'!N:N,$H15))) | D15: =IF($H15="","",IF(INDEX('Time Entries'!G:G,$H15)="","",INDEX('Time Entries'!F:F,$H15))) | E15: =IF($H15="","",IF(INDEX('Time Entries'!G:G,$H15)="","",INDEX('Time Entries'!G:G,$H15))) | F15: =IF($H15="","",IF(INDEX('Time Entries'!G:G,$H15)="","",INDEX('Time Entries'!J:J,$H15))) | G15: =IF($H15="","",IF(INDEX('Time Entries'!G:G,$H15)="","",INDEX('Time Entries'!K:K,$H15))) | H15: =IF(AND($I$4>=ROW()-3,$H$4<>""),$H$4+ROW()-4,"")
A16: =IF($H16="","",IF(INDEX('Time Entries'!G:G,$H16)="","",INDEX('Time Entries'!G:G,$H16)&" - "&INDEX('Time Entries'!H:H,$H16))) | B16: =IF($H16="","",IF(INDEX('Time Entries'!G:G,$H16)="","",INDEX('Time Entries'!M:M,$H16))) | C16: =IF($H16="","",IF(INDEX('Time Entries'!G:G,$H16)="","",INDEX('Time Entries'!N:N,$H16))) | D16: =IF($H16="","",IF(INDEX('Time Entries'!G:G,$H16)="","",INDEX('Time Entries'!F:F,$H16))) | E16: =IF($H16="","",IF(INDEX('Time Entries'!G:G,$H16)="","",INDEX('Time Entries'!G:G,$H16))) | F16: =IF($H16="","",IF(INDEX('Time Entries'!G:G,$H16)="","",INDEX('Time Entries'!J:J,$H16))) | G16: =IF($H16="","",IF(INDEX('Time Entries'!G:G,$H16)="","",INDEX('Time Entries'!K:K,$H16))) | H16: =IF(AND($I$4>=ROW()-3,$H$4<>""),$H$4+ROW()-4,"")
... A63: =IF($H63="","",IF(INDEX('Time Entries'!G:G,$H63)="","",INDEX('Time Entries'!G:G,$H63)&" - "&INDEX('Time Entries'!H:H,$H63))) | B63: =IF($H63="","",IF(INDEX('Time Entries'!G:G,$H63)="","",INDEX('Time Entries'!M:M,$H63))) | C63: =IF($H63="","",IF(INDEX('Time Entries'!G:G,$H63)="","",INDEX('Time Entries'!N:N,$H63))) | D63: =IF($H63="","",IF(INDEX('Time Entries'!G:G,$H63)="","",INDEX('Time Entries'!F:F,$H63))) | E63: =IF($H63="","",IF(INDEX('Time Entries'!G:G,$H63)="","",INDEX('Time Entries'!G:G,$H63))) | F63: =IF($H63="","",IF(INDEX('Time Entries'!G:G,$H63)="","",INDEX('Time Entries'!J:J,$H63))) | G63: =IF($H63="","",IF(INDEX('Time Entries'!G:G,$H63)="","",INDEX('Time Entries'!K:K,$H63))) | H63: =IF(AND($I$4>=ROW()-3,$H$4<>""),$H$4+ROW()-4,"")
A65: DAY SUMMARY
A66: Total Hours: | B66: =SUM(F4:F63)
A67: Working Day: | B67: 7.50 h
A68: % Utilized: | B68: =IF(F66=0,"N/A",F66/7.5)
A69: Status: | B69: =IF(F66=0,"No entries",IF(F66>=7.5,"Full day","Partial: "&TEXT(7.5-F66,"0.00")&"h remaining"))

Sheet Monthly
A1: Monthly Performance | I1: LatestDate | J1: MonthStart | K1: MonthEnd
A2: ="Month: "&TEXT(J2,"mm-yyyy") | I2: =MAX('Time Entries'!A:A) | J2: =DATE(YEAR(I2),MONTH(I2),1) | K2: =EOMONTH(I2,0)
A3: Code | B3: Father Task | C3: Project | D3: Total Hours | E3: Deadline (h) | F3: % Performance | G3: Status | H3: Completed Date
A4: =IF(KPIs!A2="","",KPIs!A2) | B4: =IF(KPIs!B2="","",KPIs!B2) | C4: =IF($B4="","",INDEX(KPIs!C:C,MATCH($B4,KPIs!B:B,0))) | D4: =IF($B4="","",SUMIFS('Time Entries'!J:J,'Time Entries'!N:N,$B4,'Time Entries'!A:A,">="&$J$2,'Time Entries'!A:A,"<="&$K$2)) | E4: =IF($B4="","",INDEX(KPIs!F:F,MATCH($B4,KPIs!B:B,0))) | F4: =IF(OR($B4="",E4=0),"",D4/E4*100) | G4: =IF($B4="","",INDEX(KPIs!G:G,MATCH($B4,KPIs!B:B,0))) | H4: =IF($B4="","",INDEX(KPIs!H:H,MATCH($B4,KPIs!B:B,0)))
A5: =IF(KPIs!A3="","",KPIs!A3) | B5: =IF(KPIs!B3="","",KPIs!B3) | C5: =IF($B5="","",INDEX(KPIs!C:C,MATCH($B5,KPIs!B:B,0))) | D5: =IF($B5="","",SUMIFS('Time Entries'!J:J,'Time Entries'!N:N,$B5,'Time Entries'!A:A,">="&$J$2,'Time Entries'!A:A,"<="&$K$2)) | E5: =IF($B5="","",INDEX(KPIs!F:F,MATCH($B5,KPIs!B:B,0))) | F5: =IF(OR($B5="",E5=0),"",D5/E5*100) | G5: =IF($B5="","",INDEX(KPIs!G:G,MATCH($B5,KPIs!B:B,0))) | H5: =IF($B5="","",INDEX(KPIs!H:H,MATCH($B5,KPIs!B:B,0)))
A6: =IF(KPIs!A4="","",KPIs!A4) | B6: =IF(KPIs!B4="","",KPIs!B4) | C6: =IF($B6="","",INDEX(KPIs!C:C,MATCH($B6,KPIs!B:B,0))) | D6: =IF($B6="","",SUMIFS('Time Entries'!J:J,'Time Entries'!N:N,$B6,'Time Entries'!A:A,">="&$J$2,'Time Entries'!A:A,"<="&$K$2)) | E6: =IF($B6="","",INDEX(KPIs!F:F,MATCH($B6,KPIs!B:B,0))) | F6: =IF(OR($B6="",E6=0),"",D6/E6*100) | G6: =IF($B6="","",INDEX(KPIs!G:G,MATCH($B6,KPIs!B:B,0))) | H6: =IF($B6="","",INDEX(KPIs!H:H,MATCH($B6,KPIs!B:B,0)))
A7: =IF(KPIs!A5="","",KPIs!A5) | B7: =IF(KPIs!B5="","",KPIs!B5) | C7: =IF($B7="","",INDEX(KPIs!C:C,MATCH($B7,KPIs!B:B,0))) | D7: =IF($B7="","",SUMIFS('Time Entries'!J:J,'Time Entries'!N:N,$B7,'Time Entries'!A:A,">="&$J$2,'Time Entries'!A:A,"<="&$K$2)) | E7: =IF($B7="","",INDEX(KPIs!F:F,MATCH($B7,KPIs!B:B,0))) | F7: =IF(OR($B7="",E7=0),"",D7/E7*100) | G7: =IF($B7="","",INDEX(KPIs!G:G,MATCH($B7,KPIs!B:B,0))) | H7: =IF($B7="","",INDEX(KPIs!H:H,MATCH($B7,KPIs!B:B,0)))
A8: =IF(KPIs!A6="","",KPIs!A6) | B8: =IF(KPIs!B6="","",KPIs!B6) | C8: =IF($B8="","",INDEX(KPIs!C:C,MATCH($B8,KPIs!B:B,0))) | D8: =IF($B8="","",SUMIFS('Time Entries'!J:J,'Time Entries'!N:N,$B8,'Time Entries'!A:A,">="&$J$2,'Time Entries'!A:A,"<="&$K$2)) | E8: =IF($B8="","",INDEX(KPIs!F:F,MATCH($B8,KPIs!B:B,0))) | F8: =IF(OR($B8="",E8=0),"",D8/E8*100) | G8: =IF($B8="","",INDEX(KPIs!G:G,MATCH($B8,KPIs!B:B,0))) | H8: =IF($B8="","",INDEX(KPIs!H:H,MATCH($B8,KPIs!B:B,0)))
A9: =IF(KPIs!A7="","",KPIs!A7) | B9: =IF(KPIs!B7="","",KPIs!B7) | C9: =IF($B9="","",INDEX(KPIs!C:C,MATCH($B9,KPIs!B:B,0))) | D9: =IF($B9="","",SUMIFS('Time Entries'!J:J,'Time Entries'!N:N,$B9,'Time Entries'!A:A,">="&$J$2,'Time Entries'!A:A,"<="&$K$2)) | E9: =IF($B9="","",INDEX(KPIs!F:F,MATCH($B9,KPIs!B:B,0))) | F9: =IF(OR($B9="",E9=0),"",D9/E9*100) | G9: =IF($B9="","",INDEX(KPIs!G:G,MATCH($B9,KPIs!B:B,0))) | H9: =IF($B9="","",INDEX(KPIs!H:H,MATCH($B9,KPIs!B:B,0)))
A10: =IF(KPIs!A8="","",KPIs!A8) | B10: =IF(KPIs!B8="","",KPIs!B8) | C10: =IF($B10="","",INDEX(KPIs!C:C,MATCH($B10,KPIs!B:B,0))) | D10: =IF($B10="","",SUMIFS('Time Entries'!J:J,'Time Entries'!N:N,$B10,'Time Entries'!A:A,">="&$J$2,'Time Entries'!A:A,"<="&$K$2)) | E10: =IF($B10="","",INDEX(KPIs!F:F,MATCH($B10,KPIs!B:B,0))) | F10: =IF(OR($B10="",E10=0),"",D10/E10*100) | G10: =IF($B10="","",INDEX(KPIs!G:G,MATCH($B10,KPIs!B:B,0))) | H10: =IF($B10="","",INDEX(KPIs!H:H,MATCH($B10,KPIs!B:B,0)))
A11: =IF(KPIs!A9="","",KPIs!A9) | B11: =IF(KPIs!B9="","",KPIs!B9) | C11: =IF($B11="","",INDEX(KPIs!C:C,MATCH($B11,KPIs!B:B,0))) | D11: =IF($B11="","",SUMIFS('Time Entries'!J:J,'Time Entries'!N:N,$B11,'Time Entries'!A:A,">="&$J$2,'Time Entries'!A:A,"<="&$K$2)) | E11: =IF($B11="","",INDEX(KPIs!F:F,MATCH($B11,KPIs!B:B,0))) | F11: =IF(OR($B11="",E11=0),"",D11/E11*100) | G11: =IF($B11="","",INDEX(KPIs!G:G,MATCH($B11,KPIs!B:B,0))) | H11: =IF($B11="","",INDEX(KPIs!H:H,MATCH($B11,KPIs!B:B,0)))
A12: =IF(KPIs!A10="","",KPIs!A10) | B12: =IF(KPIs!B10="","",KPIs!B10) | C12: =IF($B12="","",INDEX(KPIs!C:C,MATCH($B12,KPIs!B:B,0))) | D12: =IF($B12="","",SUMIFS('Time Entries'!J:J,'Time Entries'!N:N,$B12,'Time Entries'!A:A,">="&$J$2,'Time Entries'!A:A,"<="&$K$2)) | E12: =IF($B12="","",INDEX(KPIs!F:F,MATCH($B12,KPIs!B:B,0))) | F12: =IF(OR($B12="",E12=0),"",D12/E12*100) | G12: =IF($B12="","",INDEX(KPIs!G:G,MATCH($B12,KPIs!B:B,0))) | H12: =IF($B12="","",INDEX(KPIs!H:H,MATCH($B12,KPIs!B:B,0)))
A13: =IF(KPIs!A11="","",KPIs!A11) | B13: =IF(KPIs!B11="","",KPIs!B11) | C13: =IF($B13="","",INDEX(KPIs!C:C,MATCH($B13,KPIs!B:B,0))) | D13: =IF($B13="","",SUMIFS('Time Entries'!J:J,'Time Entries'!N:N,$B13,'Time Entries'!A:A,">="&$J$2,'Time Entries'!A:A,"<="&$K$2)) | E13: =IF($B13="","",INDEX(KPIs!F:F,MATCH($B13,KPIs!B:B,0))) | F13: =IF(OR($B13="",E13=0),"",D13/E13*100) | G13: =IF($B13="","",INDEX(KPIs!G:G,MATCH($B13,KPIs!B:B,0))) | H13: =IF($B13="","",INDEX(KPIs!H:H,MATCH($B13,KPIs!B:B,0)))
A14: =IF(KPIs!A12="","",KPIs!A12) | B14: =IF(KPIs!B12="","",KPIs!B12) | C14: =IF($B14="","",INDEX(KPIs!C:C,MATCH($B14,KPIs!B:B,0))) | D14: =IF($B14="","",SUMIFS('Time Entries'!J:J,'Time Entries'!N:N,$B14,'Time Entries'!A:A,">="&$J$2,'Time Entries'!A:A,"<="&$K$2)) | E14: =IF($B14="","",INDEX(KPIs!F:F,MATCH($B14,KPIs!B:B,0))) | F14: =IF(OR($B14="",E14=0),"",D14/E14*100) | G14: =IF($B14="","",INDEX(KPIs!G:G,MATCH($B14,KPIs!B:B,0))) | H14: =IF($B14="","",INDEX(KPIs!H:H,MATCH($B14,KPIs!B:B,0)))
A15: =IF(KPIs!A13="","",KPIs!A13) | B15: =IF(KPIs!B13="","",KPIs!B13) | C15: =IF($B15="","",INDEX(KPIs!C:C,MATCH($B15,KPIs!B:B,0))) | D15: =IF($B15="","",SUMIFS('Time Entries'!J:J,'Time Entries'!N:N,$B15,'Time Entries'!A:A,">="&$J$2,'Time Entries'!A:A,"<="&$K$2)) | E15: =IF($B15="","",INDEX(KPIs!F:F,MATCH($B15,KPIs!B:B,0))) | F15: =IF(OR($B15="",E15=0),"",D15/E15*100) | G15: =IF($B15="","",INDEX(KPIs!G:G,MATCH($B15,KPIs!B:B,0))) | H15: =IF($B15="","",INDEX(KPIs!H:H,MATCH($B15,KPIs!B:B,0)))
... A53: =IF(KPIs!A51="","",KPIs!A51) | B53: =IF(KPIs!B51="","",KPIs!B51) | C53: =IF($B53="","",INDEX(KPIs!C:C,MATCH($B53,KPIs!B:B,0))) | D53: =IF($B53="","",SUMIFS('Time Entries'!J:J,'Time Entries'!N:N,$B53,'Time Entries'!A:A,">="&$J$2,'Time Entries'!A:A,"<="&$K$2)) | E53: =IF($B53="","",INDEX(KPIs!F:F,MATCH($B53,KPIs!B:B,0))) | F53: =IF(OR($B53="",E53=0),"",D53/E53*100) | G53: =IF($B53="","",INDEX(KPIs!G:G,MATCH($B53,KPIs!B:B,0))) | H53: =IF($B53="","",INDEX(KPIs!H:H,MATCH($B53,KPIs!B:B,0)))
A55: MONTHLY SUMMARY
A56: Total Hours (all tasks): | B56: =SUM(D4:D53)
A57: Avg Performance: | B57: =AVERAGE(F4:F53)
A58: Tasks On Time: | B58: =COUNTIF(G4:G53,"Done")
A59: Tasks Late: | B59: =COUNTIF(G4:G53,"Late")
A60: Overall: | B60: =IF(COUNTIF(G4:G53,"Late")>0,"Needs attention","All on track")
